{
 "cells": [
  {
   "cell_type": "code",
   "execution_count": 15,
   "metadata": {},
   "outputs": [],
   "source": [
    "# test the AWS serverless API with a random 768-dim array\n",
    "import requests\n",
    "import json\n",
    "import numpy as np"
   ]
  },
  {
   "cell_type": "code",
   "execution_count": 16,
   "metadata": {},
   "outputs": [],
   "source": [
    "# create a random vector\n",
    "x = np.random.rand(768).tolist()"
   ]
  },
  {
   "cell_type": "code",
   "execution_count": 17,
   "metadata": {},
   "outputs": [],
   "source": [
    "# create a request\n",
    "url = 'https://dpl7g9n17h.execute-api.us-east-1.amazonaws.com/dev/retrieve'"
   ]
  },
  {
   "cell_type": "code",
   "execution_count": 10,
   "metadata": {},
   "outputs": [],
   "source": [
    "# we need to pass `vector` to the API.\n",
    "data = {'vector': x}"
   ]
  },
  {
   "cell_type": "code",
   "execution_count": 14,
   "metadata": {},
   "outputs": [
    {
     "ename": "ConnectionError",
     "evalue": "HTTPSConnectionPool(host='olw2x4j2g0.execute-api.us-east-1.amazonaws.com', port=443): Max retries exceeded with url: /dev/retrieve (Caused by NameResolutionError(\"<urllib3.connection.HTTPSConnection object at 0x1187bebd0>: Failed to resolve 'olw2x4j2g0.execute-api.us-east-1.amazonaws.com' ([Errno 8] nodename nor servname provided, or not known)\"))",
     "output_type": "error",
     "traceback": [
      "\u001b[0;31m---------------------------------------------------------------------------\u001b[0m",
      "\u001b[0;31mgaierror\u001b[0m                                  Traceback (most recent call last)",
      "File \u001b[0;32m~/Repos/pubmed-vector-search/urllib3/connection.py:198\u001b[0m, in \u001b[0;36m_new_conn\u001b[0;34m(self)\u001b[0m\n",
      "File \u001b[0;32m~/Repos/pubmed-vector-search/urllib3/util/connection.py:60\u001b[0m, in \u001b[0;36mcreate_connection\u001b[0;34m(address, timeout, source_address, socket_options)\u001b[0m\n",
      "File \u001b[0;32m~/anaconda3/lib/python3.11/socket.py:962\u001b[0m, in \u001b[0;36mgetaddrinfo\u001b[0;34m(host, port, family, type, proto, flags)\u001b[0m\n\u001b[1;32m    961\u001b[0m addrlist \u001b[38;5;241m=\u001b[39m []\n\u001b[0;32m--> 962\u001b[0m \u001b[38;5;28;01mfor\u001b[39;00m res \u001b[38;5;129;01min\u001b[39;00m _socket\u001b[38;5;241m.\u001b[39mgetaddrinfo(host, port, family, \u001b[38;5;28mtype\u001b[39m, proto, flags):\n\u001b[1;32m    963\u001b[0m     af, socktype, proto, canonname, sa \u001b[38;5;241m=\u001b[39m res\n",
      "\u001b[0;31mgaierror\u001b[0m: [Errno 8] nodename nor servname provided, or not known",
      "\nThe above exception was the direct cause of the following exception:\n",
      "\u001b[0;31mNameResolutionError\u001b[0m                       Traceback (most recent call last)",
      "File \u001b[0;32m~/Repos/pubmed-vector-search/urllib3/connectionpool.py:793\u001b[0m, in \u001b[0;36murlopen\u001b[0;34m(self, method, url, body, headers, retries, redirect, assert_same_host, timeout, pool_timeout, release_conn, chunked, body_pos, preload_content, decode_content, **response_kw)\u001b[0m\n",
      "File \u001b[0;32m~/Repos/pubmed-vector-search/urllib3/connectionpool.py:491\u001b[0m, in \u001b[0;36m_make_request\u001b[0;34m(self, conn, method, url, body, headers, retries, timeout, chunked, response_conn, preload_content, decode_content, enforce_content_length)\u001b[0m\n",
      "File \u001b[0;32m~/Repos/pubmed-vector-search/urllib3/connectionpool.py:467\u001b[0m, in \u001b[0;36m_make_request\u001b[0;34m(self, conn, method, url, body, headers, retries, timeout, chunked, response_conn, preload_content, decode_content, enforce_content_length)\u001b[0m\n",
      "File \u001b[0;32m~/Repos/pubmed-vector-search/urllib3/connectionpool.py:1099\u001b[0m, in \u001b[0;36m_validate_conn\u001b[0;34m(self, conn)\u001b[0m\n",
      "File \u001b[0;32m~/Repos/pubmed-vector-search/urllib3/connection.py:616\u001b[0m, in \u001b[0;36mconnect\u001b[0;34m(self)\u001b[0m\n",
      "File \u001b[0;32m~/Repos/pubmed-vector-search/urllib3/connection.py:205\u001b[0m, in \u001b[0;36m_new_conn\u001b[0;34m(self)\u001b[0m\n",
      "\u001b[0;31mNameResolutionError\u001b[0m: <urllib3.connection.HTTPSConnection object at 0x1187bebd0>: Failed to resolve 'olw2x4j2g0.execute-api.us-east-1.amazonaws.com' ([Errno 8] nodename nor servname provided, or not known)",
      "\nThe above exception was the direct cause of the following exception:\n",
      "\u001b[0;31mMaxRetryError\u001b[0m                             Traceback (most recent call last)",
      "File \u001b[0;32m~/anaconda3/lib/python3.11/site-packages/requests/adapters.py:589\u001b[0m, in \u001b[0;36mHTTPAdapter.send\u001b[0;34m(self, request, stream, timeout, verify, cert, proxies)\u001b[0m\n\u001b[1;32m    588\u001b[0m \u001b[38;5;28;01mtry\u001b[39;00m:\n\u001b[0;32m--> 589\u001b[0m     resp \u001b[38;5;241m=\u001b[39m conn\u001b[38;5;241m.\u001b[39murlopen(\n\u001b[1;32m    590\u001b[0m         method\u001b[38;5;241m=\u001b[39mrequest\u001b[38;5;241m.\u001b[39mmethod,\n\u001b[1;32m    591\u001b[0m         url\u001b[38;5;241m=\u001b[39murl,\n\u001b[1;32m    592\u001b[0m         body\u001b[38;5;241m=\u001b[39mrequest\u001b[38;5;241m.\u001b[39mbody,\n\u001b[1;32m    593\u001b[0m         headers\u001b[38;5;241m=\u001b[39mrequest\u001b[38;5;241m.\u001b[39mheaders,\n\u001b[1;32m    594\u001b[0m         redirect\u001b[38;5;241m=\u001b[39m\u001b[38;5;28;01mFalse\u001b[39;00m,\n\u001b[1;32m    595\u001b[0m         assert_same_host\u001b[38;5;241m=\u001b[39m\u001b[38;5;28;01mFalse\u001b[39;00m,\n\u001b[1;32m    596\u001b[0m         preload_content\u001b[38;5;241m=\u001b[39m\u001b[38;5;28;01mFalse\u001b[39;00m,\n\u001b[1;32m    597\u001b[0m         decode_content\u001b[38;5;241m=\u001b[39m\u001b[38;5;28;01mFalse\u001b[39;00m,\n\u001b[1;32m    598\u001b[0m         retries\u001b[38;5;241m=\u001b[39m\u001b[38;5;28mself\u001b[39m\u001b[38;5;241m.\u001b[39mmax_retries,\n\u001b[1;32m    599\u001b[0m         timeout\u001b[38;5;241m=\u001b[39mtimeout,\n\u001b[1;32m    600\u001b[0m         chunked\u001b[38;5;241m=\u001b[39mchunked,\n\u001b[1;32m    601\u001b[0m     )\n\u001b[1;32m    603\u001b[0m \u001b[38;5;28;01mexcept\u001b[39;00m (ProtocolError, \u001b[38;5;167;01mOSError\u001b[39;00m) \u001b[38;5;28;01mas\u001b[39;00m err:\n",
      "File \u001b[0;32m~/Repos/pubmed-vector-search/urllib3/connectionpool.py:847\u001b[0m, in \u001b[0;36murlopen\u001b[0;34m(self, method, url, body, headers, retries, redirect, assert_same_host, timeout, pool_timeout, release_conn, chunked, body_pos, preload_content, decode_content, **response_kw)\u001b[0m\n",
      "File \u001b[0;32m~/Repos/pubmed-vector-search/urllib3/util/retry.py:515\u001b[0m, in \u001b[0;36mincrement\u001b[0;34m(self, method, url, response, error, _pool, _stacktrace)\u001b[0m\n",
      "\u001b[0;31mMaxRetryError\u001b[0m: HTTPSConnectionPool(host='olw2x4j2g0.execute-api.us-east-1.amazonaws.com', port=443): Max retries exceeded with url: /dev/retrieve (Caused by NameResolutionError(\"<urllib3.connection.HTTPSConnection object at 0x1187bebd0>: Failed to resolve 'olw2x4j2g0.execute-api.us-east-1.amazonaws.com' ([Errno 8] nodename nor servname provided, or not known)\"))",
      "\nDuring handling of the above exception, another exception occurred:\n",
      "\u001b[0;31mConnectionError\u001b[0m                           Traceback (most recent call last)",
      "Cell \u001b[0;32mIn[14], line 2\u001b[0m\n\u001b[1;32m      1\u001b[0m \u001b[38;5;66;03m# now execute the API and print the response\u001b[39;00m\n\u001b[0;32m----> 2\u001b[0m response \u001b[38;5;241m=\u001b[39m requests\u001b[38;5;241m.\u001b[39mpost(url, data\u001b[38;5;241m=\u001b[39mjson\u001b[38;5;241m.\u001b[39mdumps(data))\n\u001b[1;32m      3\u001b[0m \u001b[38;5;28mprint\u001b[39m(response\u001b[38;5;241m.\u001b[39mtext)\n",
      "File \u001b[0;32m~/anaconda3/lib/python3.11/site-packages/requests/api.py:115\u001b[0m, in \u001b[0;36mpost\u001b[0;34m(url, data, json, **kwargs)\u001b[0m\n\u001b[1;32m    103\u001b[0m \u001b[38;5;28;01mdef\u001b[39;00m \u001b[38;5;21mpost\u001b[39m(url, data\u001b[38;5;241m=\u001b[39m\u001b[38;5;28;01mNone\u001b[39;00m, json\u001b[38;5;241m=\u001b[39m\u001b[38;5;28;01mNone\u001b[39;00m, \u001b[38;5;241m*\u001b[39m\u001b[38;5;241m*\u001b[39mkwargs):\n\u001b[1;32m    104\u001b[0m \u001b[38;5;250m    \u001b[39m\u001b[38;5;124mr\u001b[39m\u001b[38;5;124;03m\"\"\"Sends a POST request.\u001b[39;00m\n\u001b[1;32m    105\u001b[0m \n\u001b[1;32m    106\u001b[0m \u001b[38;5;124;03m    :param url: URL for the new :class:`Request` object.\u001b[39;00m\n\u001b[0;32m   (...)\u001b[0m\n\u001b[1;32m    112\u001b[0m \u001b[38;5;124;03m    :rtype: requests.Response\u001b[39;00m\n\u001b[1;32m    113\u001b[0m \u001b[38;5;124;03m    \"\"\"\u001b[39;00m\n\u001b[0;32m--> 115\u001b[0m     \u001b[38;5;28;01mreturn\u001b[39;00m request(\u001b[38;5;124m\"\u001b[39m\u001b[38;5;124mpost\u001b[39m\u001b[38;5;124m\"\u001b[39m, url, data\u001b[38;5;241m=\u001b[39mdata, json\u001b[38;5;241m=\u001b[39mjson, \u001b[38;5;241m*\u001b[39m\u001b[38;5;241m*\u001b[39mkwargs)\n",
      "File \u001b[0;32m~/anaconda3/lib/python3.11/site-packages/requests/api.py:59\u001b[0m, in \u001b[0;36mrequest\u001b[0;34m(method, url, **kwargs)\u001b[0m\n\u001b[1;32m     55\u001b[0m \u001b[38;5;66;03m# By using the 'with' statement we are sure the session is closed, thus we\u001b[39;00m\n\u001b[1;32m     56\u001b[0m \u001b[38;5;66;03m# avoid leaving sockets open which can trigger a ResourceWarning in some\u001b[39;00m\n\u001b[1;32m     57\u001b[0m \u001b[38;5;66;03m# cases, and look like a memory leak in others.\u001b[39;00m\n\u001b[1;32m     58\u001b[0m \u001b[38;5;28;01mwith\u001b[39;00m sessions\u001b[38;5;241m.\u001b[39mSession() \u001b[38;5;28;01mas\u001b[39;00m session:\n\u001b[0;32m---> 59\u001b[0m     \u001b[38;5;28;01mreturn\u001b[39;00m session\u001b[38;5;241m.\u001b[39mrequest(method\u001b[38;5;241m=\u001b[39mmethod, url\u001b[38;5;241m=\u001b[39murl, \u001b[38;5;241m*\u001b[39m\u001b[38;5;241m*\u001b[39mkwargs)\n",
      "File \u001b[0;32m~/anaconda3/lib/python3.11/site-packages/requests/sessions.py:589\u001b[0m, in \u001b[0;36mSession.request\u001b[0;34m(self, method, url, params, data, headers, cookies, files, auth, timeout, allow_redirects, proxies, hooks, stream, verify, cert, json)\u001b[0m\n\u001b[1;32m    584\u001b[0m send_kwargs \u001b[38;5;241m=\u001b[39m {\n\u001b[1;32m    585\u001b[0m     \u001b[38;5;124m\"\u001b[39m\u001b[38;5;124mtimeout\u001b[39m\u001b[38;5;124m\"\u001b[39m: timeout,\n\u001b[1;32m    586\u001b[0m     \u001b[38;5;124m\"\u001b[39m\u001b[38;5;124mallow_redirects\u001b[39m\u001b[38;5;124m\"\u001b[39m: allow_redirects,\n\u001b[1;32m    587\u001b[0m }\n\u001b[1;32m    588\u001b[0m send_kwargs\u001b[38;5;241m.\u001b[39mupdate(settings)\n\u001b[0;32m--> 589\u001b[0m resp \u001b[38;5;241m=\u001b[39m \u001b[38;5;28mself\u001b[39m\u001b[38;5;241m.\u001b[39msend(prep, \u001b[38;5;241m*\u001b[39m\u001b[38;5;241m*\u001b[39msend_kwargs)\n\u001b[1;32m    591\u001b[0m \u001b[38;5;28;01mreturn\u001b[39;00m resp\n",
      "File \u001b[0;32m~/anaconda3/lib/python3.11/site-packages/requests/sessions.py:703\u001b[0m, in \u001b[0;36mSession.send\u001b[0;34m(self, request, **kwargs)\u001b[0m\n\u001b[1;32m    700\u001b[0m start \u001b[38;5;241m=\u001b[39m preferred_clock()\n\u001b[1;32m    702\u001b[0m \u001b[38;5;66;03m# Send the request\u001b[39;00m\n\u001b[0;32m--> 703\u001b[0m r \u001b[38;5;241m=\u001b[39m adapter\u001b[38;5;241m.\u001b[39msend(request, \u001b[38;5;241m*\u001b[39m\u001b[38;5;241m*\u001b[39mkwargs)\n\u001b[1;32m    705\u001b[0m \u001b[38;5;66;03m# Total elapsed time of the request (approximately)\u001b[39;00m\n\u001b[1;32m    706\u001b[0m elapsed \u001b[38;5;241m=\u001b[39m preferred_clock() \u001b[38;5;241m-\u001b[39m start\n",
      "File \u001b[0;32m~/anaconda3/lib/python3.11/site-packages/requests/adapters.py:622\u001b[0m, in \u001b[0;36mHTTPAdapter.send\u001b[0;34m(self, request, stream, timeout, verify, cert, proxies)\u001b[0m\n\u001b[1;32m    618\u001b[0m     \u001b[38;5;28;01mif\u001b[39;00m \u001b[38;5;28misinstance\u001b[39m(e\u001b[38;5;241m.\u001b[39mreason, _SSLError):\n\u001b[1;32m    619\u001b[0m         \u001b[38;5;66;03m# This branch is for urllib3 v1.22 and later.\u001b[39;00m\n\u001b[1;32m    620\u001b[0m         \u001b[38;5;28;01mraise\u001b[39;00m SSLError(e, request\u001b[38;5;241m=\u001b[39mrequest)\n\u001b[0;32m--> 622\u001b[0m     \u001b[38;5;28;01mraise\u001b[39;00m \u001b[38;5;167;01mConnectionError\u001b[39;00m(e, request\u001b[38;5;241m=\u001b[39mrequest)\n\u001b[1;32m    624\u001b[0m \u001b[38;5;28;01mexcept\u001b[39;00m ClosedPoolError \u001b[38;5;28;01mas\u001b[39;00m e:\n\u001b[1;32m    625\u001b[0m     \u001b[38;5;28;01mraise\u001b[39;00m \u001b[38;5;167;01mConnectionError\u001b[39;00m(e, request\u001b[38;5;241m=\u001b[39mrequest)\n",
      "\u001b[0;31mConnectionError\u001b[0m: HTTPSConnectionPool(host='olw2x4j2g0.execute-api.us-east-1.amazonaws.com', port=443): Max retries exceeded with url: /dev/retrieve (Caused by NameResolutionError(\"<urllib3.connection.HTTPSConnection object at 0x1187bebd0>: Failed to resolve 'olw2x4j2g0.execute-api.us-east-1.amazonaws.com' ([Errno 8] nodename nor servname provided, or not known)\"))"
     ]
    }
   ],
   "source": [
    "# now execute the API and print the response\n",
    "response = requests.post(url, data=json.dumps(data))\n",
    "print(response.text)"
   ]
  }
 ],
 "metadata": {
  "kernelspec": {
   "display_name": "base",
   "language": "python",
   "name": "python3"
  },
  "language_info": {
   "codemirror_mode": {
    "name": "ipython",
    "version": 3
   },
   "file_extension": ".py",
   "mimetype": "text/x-python",
   "name": "python",
   "nbconvert_exporter": "python",
   "pygments_lexer": "ipython3",
   "version": "3.11.9"
  }
 },
 "nbformat": 4,
 "nbformat_minor": 2
}
